Workbook

Sheet Instructions
B2: სათბურის ფულადი ნაკადები / GREENHOUSE CASH-FLOW MODEL
B3: 2,000 m² · წელიწადში 2 მოსავალი / two harvest cycles per year · საბანკო სესხი / bank loan USD 140,000
B6: როგორ ვიმუშაოთ / HOW TO USE
B7: 1. Assumptions | C7: ყველა დაშვება აქ იცვლება. მხოლოდ ლურჯი და ყვითელი უჯრები შეავსეთ. / All drivers live here. Edit ONLY the blue and yellow cells.
B8: 2. OPEX | C8: 150,000 GEL წლიური ხარჯის დაშლა 8 კატეგორიად + სეზონურობა თვეების მიხედვით. / The 150,000 GEL annual OPEX split into 8 categories with monthly seasonality.
B9: Loan | C9: 625,000 ₾ კრედიტის 120-თვიანი გრაფიკი სააგენტოს თანადაფინანსებით, ბანკის დანართ #1-თან შედარებით. / The 120-month schedule of the 625,000 GEL credit with the agency co-financing, checked against the bank Annex 1.
B10: 4. CF_Monthly | C10: წელი 1 — თვიური ფულადი ნაკადი (იან–დეკ). მთავარი ცხრილი. / Year 1 monthly cash flow (Jan–Dec). The main statement.
B11: 5. Annual | C11: წლები 1–5 — შემოსავალი, EBITDA, ვალის მომსახურება, DSCR. / Years 1–5 summary: revenue, EBITDA, debt service, DSCR.
B12: 6. Sensitivity | C12: ფასისა და მოსავლიანობის მგრძნობელობა + წაგება-მოგების ზღვარი. / Price & yield sensitivity plus break-even.
B13: 7. Actuals | C13: შპს მუხრანი 2026-ის ბანკის ამონაწერი — ფაქტობრივი გადარიცხვები 01/07–08/09/2026. / LLC Mukhrani 2026 bank statement — actual payments 1 Jul – 8 Sep 2026.
B14: Budget | C14: ბიუჯეტი 625,000 ₾ და სად ვართ: დახარჯული, ვალდებული, თავისუფალი ნაშთი, ხარჯი კატეგორიებად და თვეებად. / The 625,000 GEL budget and where it stands: spent, committed, free, by category and by month.
B16: ფერების ლეგენდა / COLOUR LEGEND
B17: ლურჯი ციფრი / Blue number | C17: ხელით შეყვანილი დაშვება — შეცვალეთ თავისუფლად. / Hardcoded input — edit freely.
B18: ყვითელი ფონი / Yellow fill | C18: კრიტიკული დაშვება, გადაამოწმეთ. / Key assumption, verify before use.
B19: შავი ციფრი / Black number | C19: ფორმულა — ნუ შეცვლით. / Formula — do not overwrite.
B20: მწვანე ციფრი / Green number | C20: სხვა ფურცელზე მიბმული ფორმულა. / Link to another sheet.
B22: წყაროები და დაშვებები / SOURCES & ASSUMPTIONS
B23: ფართობი / Area — 2,000 m² | C23: მომხმარებლის მონაცემი / Given by the user.
B24: ციკლები / Cycles — 2 per year | C24: მომხმარებლის მონაცემი / Given by the user.
B25: ზამთრის მოსავალი / Winter harvest — 85 t (80–90 range) | C25: მომხმარებელმა მიუთითა „80-90 kg". 2,000 m²-ზე ეს ფიზიკურად ტონებია (42.5 kg/m²), ამიტომ მოდელში ჩადებულია 85 ტონა (80–90-ის შუალედი). თუ სხვა რიცხვია — შეცვალეთ Assumptions!B10. / User wrote "80-90 kg"; for 2,000 m² this can only mean tonnes (42.5 kg/m²), so 85 t (mid-range) is used. Correct Assumptions!B10 if the intent differed.
B26: ზამთრის ფასი / Winter price — 4.50 GEL/kg | C26: მომხმარებლის მონაცემი / Given by the user.
B27: ზაფხულის მოსავალი / Summer harvest — 70 t | C27: მომხმარებლის მონაცემი / Given by the user (35 kg/m²).
B28: ზაფხულის ფასი / Summer price — 3.00 GEL/kg | C28: მომხმარებლის მონაცემი / Given by the user.
B29: OPEX — 150,000 GEL/წელი | C29: მომხმარებლის მონაცემი. 8 კატეგორიად დაშლა და თვიური სეზონურობა მოდელის დაშვებაა — შეცვლადია OPEX ფურცელზე. / Total given by the user; the split into 8 categories and the monthly seasonality are the model's own assumptions and are editable on the OPEX sheet.
B30: კრედიტი / Credit — 625,000 ₾, სს „ბანკი ქართუ" | C30: ხელშეკრულება GA/1-876787–001, 17/06/2026, მსესხებელი შპს მუხრანი 2026 (ს/ნ 404801602); ვადა 17/06/2036, 120 თვე; შეღავათიანი აგრო კრედიტი, მიზნობრიობა — ძირითადი საშუალებების ფინანსირება (პუნქტები 3.6, 3.8, 3.11). / Contract GA/1-876787–001 of 17/06/2026 with LLC Mukhrani 2026; matures 17/06/2036 over 120 months; preferential agro credit for financing fixed assets (clauses 3.6, 3.8, 3.11).
B31: განაკვეთი / Rate — 12.64%, შემდეგ 13.40% | C31: 12.64% 17/06/2028-მდე; შემდეგ ინდექსირებული = რეფინანსირება + 5.14%, არანაკლებ 10% და არაუმეტეს 18%. ეფექტური 13.77% / 13.78%. მე-2 განაკვეთი 13.40% ბანკის დანართ #1-იდანაა ნაგულისხმევი (რეფინანსირება 8.26% + 5.14%). / 12.64% to 17/06/2028, then indexed at refinancing + 5.14%, floor 10%, cap 18%. Effective APR 13.77% / 13.78%. The 13.40% second rate is what the bank's own Annex 1 implies (refinancing 8.26% + 5.14%).
B32: თანადაფინანსება / Co-financing — 11% p.a., 48 თვე | C32: სოფლის განვითარების სააგენტო აფინანსებს ძირითადი თანხის წლიურ 11%-ს, არაუმეტეს 48 თვისა (პუნქტი 3.5). მოდელში ეს ამცირებს პროცენტის ტვირთს დაახლოებით 256,000 ₾-ით. / The Rural Development Agency co-finances 11% p.a. of the principal for up to 48 months (clause 3.5) — worth about 256,000 GEL of the interest bill.
B33: გრაფიკი / Schedule — 12 თვე შეღავათი | C33: დანართი #1: თვე 1–12 გადახდის გარეშე, მე-13 თვეს იფარება დაგროვილი პროცენტი, შემდეგ ანუიტეტი 107 თვის განმავლობაში. / Annex 1: months 1–12 pay nothing, month 13 clears the accrued interest, then a 107-month annuity.
B34: კურსი / FX — 2.6384 ₾/$ | C34: ფაქტი: ბანკის ამონაწერი 09/07/2026 — 22,000 USD = 58,044.80 GEL, დანიშნულებაში მითითებული კურსი 2.6384. (04/08/2026: 5,000 USD = 13,100 GEL → 2.62.) / Actual: bank statement 09/07/2026 — USD 22,000 = GEL 58,044.80, rate 2.6384 stated in the payment description. (04/08/2026: USD 5,000 = GEL 13,100 → 2.62.)
... B41: შენიშვნა / NOTE | C41: ეს არის ფინანსური მოდელი დაშვებებზე დაყრდნობით და არა საინვესტიციო რჩევა. / This is an assumption-driven model, not investment advice.

Sheet Budget
A1: ბიუჯეტი და გახარჯვა / BUDGET AND SPEND
A2: ბიუჯეტი — 625,000 ₾ კრედიტი. გახარჯვა — ბანკის ამონაწერი (Actuals). / The budget is the 625,000 GEL credit; the spend is the bank statement on the Actuals sheet.
A4: 1. სად ვართ / WHERE WE ARE
A5: მაჩვენებელი / Item | B5: GEL | C5: % ბიუჯეტიდან / of budget | D5: ინდიკატორი / Bar
A6: ბიუჯეტი — კრედიტი / BUDGET — the credit | B6: =Assumptions!$B$27 -> 625000 | C6: =IFERROR(B6/$B$6,0) -> 1 | D6: =REPT("|",ROUND(C6*40,0)) -> ||||||||||||||||||||||||||||||||||||||||
A7: დახარჯული დღემდე / SPENT to date | B7: =B26 -> 210261.64 | C7: =IFERROR(B7/$B$6,0) -> 0.33641862 | D7: =REPT("|",ROUND(C7*40,0)) -> |||||||||||||
A8: ავანსი დირექტორზე / ADVANCE issued to the director | B8: =SUMIF($D$16:$D$25,"ADVANCE",$B$16:$B$25) -> 10000 | C8: =IFERROR(B8/$B$6,0) -> 0.016 | D8: =REPT("|",ROUND(C8*40,0)) -> |
A9: აქედან ანგარიშგებულია / of which already accounted for by receipts | B9: 3019.65 | C9: =IFERROR(B9/$B$6,0) -> 0.00483144 | D9: =REPT("|",ROUND(C9*40,0))
A10: ვალდებულება — ხელშეკრულებების ნაშთი / COMMITTED — contracts outstanding | B10: =D41 -> 176511.2 | C10: =IFERROR(B10/$B$6,0) -> 0.28241792 | D10: =REPT("|",ROUND(C10*40,0)) -> |||||||||||
A11: სულ დახარჯული ან ვალდებული / USED or COMMITTED | B11: =B7+(B8-B9)+B10 -> 393753.19 | C11: =IFERROR(B11/$B$6,0) -> 0.6300051 | D11: =REPT("|",ROUND(C11*40,0)) -> |||||||||||||||||||||||||
A12: თავისუფალი ნაშთი / FREE budget left | B12: =B6-B11 -> 231246.81 | C12: =IFERROR(B12/$B$6,0) -> 0.3699949 | D12: =REPT("|",ROUND(C12*40,0)) -> |||||||||||||||
A14: 2. გახარჯვა კატეგორიებად / SPEND BY CATEGORY
A15: კატეგორია / Category | B15: დახარჯული GEL / Spent | C15: % ხარჯიდან / of spend | D15: კლასიფიკაცია / Treatment | E15: დაგეგმილი / Planned | F15: სხვაობა / Variance
A16: მშენებლობის ავანსი / Construction advance | B16: =Actuals!B68 -> 178544.8 | C16: =IFERROR(B16/$B$26,0) -> 0.84915537 | D16: CAPEX | F16: =IF(E16="","",E16-B16) | G16: ყვითელი სვეტი ცარიელია — შეავსეთ, თუ კატეგორიებად გეგმა გაქვთ. / The yellow column is empty — fill it in if you have a plan per category.
A17: ხელფასი / Salaries | B17: =Actuals!B69 -> 10000 | C17: =IFERROR(B17/$B$26,0) -> 0.047559793 | D17: OPEX | F17: =IF(E17="","",E17-B17)
A18: გადასახადები / Taxes & pension | B18: =Actuals!B70 -> 1470 | C18: =IFERROR(B18/$B$26,0) -> 0.0069912895 | D18: OPEX | F18: =IF(E18="","",E18-B18)
A19: მომსახურება / Services | B19: =Actuals!B71 -> 3070 | C19: =IFERROR(B19/$B$26,0) -> 0.014600856 | D19: OPEX | F19: =IF(E19="","",E19-B19)
A20: საწვავი / Fuel | B20: =Actuals!B72 -> 3019.65 | C20: =IFERROR(B20/$B$26,0) -> 0.014361393 | D20: OPEX | F20: =IF(E20="","",E20-B20)
A21: მუშების კვება / Worker meals | B21: =Actuals!B73 -> 0 | C21: =IFERROR(B21/$B$26,0) -> 0 | D21: OPEX | F21: =IF(E21="","",E21-B21)
A22: მასალები / Materials | B22: =Actuals!B74 -> 5722.7 | C22: =IFERROR(B22/$B$26,0) -> 0.027217043 | D22: CAPEX | F22: =IF(E22="","",E22-B22)
A23: მომწოდებლის ინვოისი / Supplier invoice | B23: =Actuals!B75 -> 7505.41 | C23: =IFERROR(B23/$B$26,0) -> 0.035695574 | D23: CAPEX | F23: =IF(E23="","",E23-B23)
A24: სხვა / Other | B24: =Actuals!B76 -> 929.08 | C24: =IFERROR(B24/$B$26,0) -> 0.0044186852 | D24: CAPEX | F24: =IF(E24="","",E24-B24)
A25: ავანსი დირექტორზე / Advance to the director | B25: =Actuals!B77 -> 10000 | C25: =IFERROR(B25/$B$26,0) -> 0.047559793 | D25: ADVANCE | F25: =IF(E25="","",E25-B25)
A26: სულ დახარჯული — ავანსის გარეშე / TOTAL SPENT, advances excluded | B26: =SUM(B16:B25)-SUMIF($D$16:$D$25,"ADVANCE",$B$16:$B$25) -> 210261.64 | C26: =IFERROR(B26/B26,0) -> 1 | E26: =IF(COUNT(E16:E25)=0,"",SUM(E16:E25)) | F26: =IF(E26="","",E26-B26)
A28: 3. ბიუჯეტის ნაშთი თვეების მიხედვით / BUDGET DRAWDOWN BY MONTH
A29: თვე / Month | B29: ხარჯი / Spend | C29: კუმულატიური / Cumulative | D29: ბიუჯეტის ნაშთი / Budget left
A30: ივლისი 2026 / July | B30: =Actuals!B83 -> 69796.68 | C30: =SUM($B$30:B30) -> 69796.68 | D30: =$B$6-C30 -> 555203.32
A31: აგვისტო 2026 / August | B31: =Actuals!B84 -> 22040.5 | C31: =SUM($B$30:B31) -> 91837.18 | D31: =$B$6-C31 -> 533162.82
A32: სექტემბერი 2026 (21-მდე) / September (to the 21st) | B32: =Actuals!B85 -> 128424.46 | C32: =SUM($B$30:B32) -> 220261.64 | D32: =$B$6-C32 -> 404738.36
A33: სულ / TOTAL | B33: =SUM(B30:B32) -> 220261.64 | C33: =B33-B26-SUMIF($D$16:$D$25,"ADVANCE",$B$16:$B$25) -> 2.910383e-11 | D33: =$B$6-B33 -> 404738.36 | G33: C33 შემოწმებაა — უნდა იყოს 0 / C33 is a check — it must read 0
A35: 4. ხელშეკრულებები — შპს ჯიესენ გრუპი / CONTRACTS — LLC GSN GROUP
A36: მუხლი / Item | B36: USD | C36: კურსი / Rate | D36: GEL
A37: N1 — სათბური / the greenhouse | B37: 125000 | C37: =Assumptions!$B$28 -> 2.6384 | D37: =B37*Assumptions!$B$28 -> 329800 | G37: ხელშეკრულება N1, 7/6/2026 / contract N1 of 7 June 2026
A38: ტექნიკური ოთახი 200 მ² — პერიმეტრის ბეტონი და ბლოკი / technical room 200 m2 — perimeter concrete and blockwork | B38: 10000 | C38: =Assumptions!$B$28 -> 2.6384 | D38: =B38*Assumptions!$B$28 -> 26384 | G38: მფლობელის მონაცემი 22/09/2026 — ხელშეკრულების ნომერი დასადასტურებელია / owner-reported 22 Sep 2026; the contract reference still needs confirming
A39: ჯამი / Total contracted | B39: =B37+B38 -> 135000 | C39: =Assumptions!$B$28 -> 2.6384 | D39: =B39*Assumptions!$B$28 -> 356184
A40: გადახდილი ავანსი / Advances paid | B40: =22000+5000+40000+2900/Assumptions!$B$28 -> 68099.151 | C40: =IFERROR(D40/B40,0) -> 2.6218359 | D40: =Actuals!B68 -> 178544.8 | G40: 09/07 — 22,000 $ · 04/08 — 5,000 $ · 14/09 — 2,900 ₾ ≈ 1,099 $ (ერ.კ. 2.6384) · 19/09 — 40,000 $ ერ.კ. 2.6125 · ყველა N1-ზე / all against N1
A41: დარჩენილი გადასახდელი / Outstanding | B41: =B39-B40 -> 66900.849 | C41: =Assumptions!$B$28 -> 2.6384 | D41: =B41*Assumptions!$B$28 -> 176511.2
A42: შესრულების წილი / Share of the contracted work paid | B42: =IFERROR(B40/B39,0) -> 0.50443816
A44: 5. კაპიტალური თუ საოპერაციო / CAPITAL OR OPERATING
A45: კაპიტალიზებული / Capitalised (CAPEX) | B45: =SUMIF($D$16:$D$25,"CAPEX",$B$16:$B$25) -> 192701.99 | C45: =IFERROR(B45/$B$26,0) -> 0.91648667 | G45: სათბურის ღირებულებაში / into the cost of the greenhouse
...

Sheet Assumptions
A1: დაშვებები / ASSUMPTIONS
A2: შეცვალეთ მხოლოდ ლურჯი/ყვითელი უჯრები / Edit blue & yellow cells only
A4: მაჩვენებელი / Item | B4: მნიშვნელობა / Value | C4: ერთეული / Unit | D4: კომენტარი / Comment
A5: 1. ობიექტი / FACILITY
A6: სათბურის ფართობი / Greenhouse area | B6: 2000 | C6: m² | D6: მომხმარებლის მონაცემი / Given
A7: მოსავლის ციკლები წელიწადში / Harvest cycles per year | B7: 2 | C7: cycles | D7: ზამთარი + ზაფხული / Winter + summer
A9: 2. მოსავალი და ფასი / YIELD & PRICE
A10: ზამთრის მოსავალი / Winter harvest | B10: 85 | C10: tons | D10: მითითებული დიაპაზონი 80–90 / Stated range 80–90; midpoint used
A11: ზამთრის მოსავალი / Winter harvest (kg) | B11: =B10*1000 -> 85000 | C11: kg | D11: ავტომატური / Calculated
A12: ზამთრის მოსავლიანობა / Winter yield per m² | B12: =B11/B6 -> 42.5 | C12: kg/m² | D12: ავტომატური / Calculated
A13: ზამთრის ფასი / Winter selling price | B13: 4.5 | C13: GEL/kg | D13: მომხმარებლის მონაცემი / Given
A14: ზაფხულის მოსავალი / Summer harvest | B14: 70 | C14: tons | D14: მომხმარებლის მონაცემი / Given
A15: ზაფხულის მოსავალი / Summer harvest (kg) | B15: =B14*1000 -> 70000 | C15: kg | D15: ავტომატური / Calculated
A16: ზაფხულის მოსავლიანობა / Summer yield per m² | B16: =B15/B6 -> 35 | C16: kg/m² | D16: ავტომატური / Calculated
A17: ზაფხულის ფასი / Summer selling price | B17: 3 | C17: GEL/kg | D17: მომხმარებლის მონაცემი / Given
A18: სულ მოსავალი / Total annual harvest | B18: =B10+B14 -> 155 | C18: tons | D18: ავტომატური / Calculated
A19: საშუალო შეწონილი ფასი / Blended average price | B19: =(B11*B13+B15*B17)/(B11+B15) -> 3.8225806 | C19: GEL/kg | D19: ავტომატური / Calculated
A21: 3. საოპერაციო ხარჯი / OPERATING EXPENSES
A22: წლიური OPEX (მითითებული) / Annual OPEX as stated | B22: 150000 | C22: GEL | D22: მომხმარებლის მონაცემი / Given
A23: OPEX ფურცლის ჯამი / Total from OPEX sheet | B23: =OPEX!B14 -> 150000 | C23: GEL | D23: 8 კატეგორიის ჯამი / Sum of the 8 categories
A24: შედარება / Check (must be 0) | B24: =B23-B22 -> 0 | C24: GEL | D24: თუ ≠ 0, გაასწორეთ OPEX კატეგორიები / If ≠ 0, adjust the OPEX categories
A26: 4. საბანკო სესხი — სს „ბანკი ქართუ" / BANK LOAN — CARTU BANK
A27: კრედიტის თანხა / Credit amount | B27: 625000 | C27: GEL | D27: ხელშეკრულება GA/1-876787–001, პუნქტი 3.11 / contract clause 3.11
A28: გაცვლითი კურსი / FX rate | B28: 2.6384 | C28: GEL/USD | D28: ფაქტი 09/07/2026 გადარიცხვიდან, USD ხელშეკრულებებისთვის / actual, used for the USD contracts
A29: მოდელში გამოყენებული ძირი / Principal used in the model (GEL) | B29: =B27 -> 625000 | C29: GEL | D29: სრულად ათვისებულად ითვლება / assumed fully drawn
A30: წლიური საპროცენტო განაკვეთი / Annual interest rate | B30: 0.1264 | C30: % | D30: 12.64% 17/06/2028-მდე; შემდეგ რეფინანსირება + 5.14%, min 10%, max 18% / 12.64% to 17/06/2028, indexed after
A31: ვადა / Term | B31: 120 | C31: months | D31: 17/06/2026 – 17/06/2036 (პუნქტი 3.9) / clause 3.9
A32: საშეღავათო პერიოდი / Grace period, no payments | B32: 12 | C32: months | D32: დანართი #1: თვე 1–12 გადახდის გარეშე / Annex 1: months 1–12 pay nothing
A33: ყოველთვიური ანუიტეტი / Monthly annuity | B33: =PMT(B30/12,B31-B32-1,-B29) -> 9766.0727 | C33: GEL | D33: 107 შენატანი მე-14 თვიდან / 107 instalments from month 14
A34: სააგენტოს თანადაფინანსება / Agency co-financing rate | B34: 0.11 | C34: % | D34: სოფლის განვითარების სააგენტო — ძირის 11% წლიურად (პუნქტი 3.5) / Rural Development Agency, clause 3.5
A35: თანადაფინანსების ვადა / Co-financing period | B35: 48 | C35: months | D35: არაუმეტეს 48 თვისა (პუნქტი 3.5) / up to 48 months, clause 3.5
A36: განაკვეთი 17/06/2028-ის შემდეგ / Rate after 17/06/2028 | B36: 0.134 | C36: % | D36: რეფინანსირება 8.26% + მარჟა 5.14%; ბანკის დანართ #1-იდან ნაგულისხმევი / implied by the bank's Annex 1: refinancing 8.26% + 5.14% margin
A37: თვე, საიდანაც მოქმედებს მე-2 განაკვეთი / Month the second rate starts | B37: 24 | C37: month | D37: 19/06/2028, გრაფიკის 24-ე შენატანი / instalment 24, 19/06/2028
A38: 5. ზრდა და ინფლაცია (წლები 2–5) / GROWTH & INFLATION (YEARS 2–5)
A39: მოსავლის ზრდა / Yield growth p.a. | B39: 0.02 | C39: % | D39: მოდელის დაშვება / Model assumption
A40: ფასის ზრდა / Price growth p.a. | B40: 0.03 | C40: % | D40: მოდელის დაშვება / Model assumption
A41: OPEX ინფლაცია / OPEX inflation p.a. | B41: 0.04 | C41: % | D41: მოდელის დაშვება / Model assumption
A43: 6. სხვა / OTHER
A44: მოგების გადასახადი / Profit tax rate applied | B44: 0 | C44: % | D44: 0% ნაგულისხმევად — იხ. Instructions / 0% by default
A45: საწყისი ფულადი ნაშთი / Opening cash balance | B45: 0 | C45: GEL | D45: საოპერაციო წელი 1-ის დასაწყისი / start of operating Year 1
...

Sheet OPEX
A1: საოპერაციო ხარჯები / OPERATING EXPENSES
A2: სულ 150,000 GEL/წელი. კატეგორიების დაშლა და თვიური წილები მოდელის დაშვებაა — შეცვლადია. / 150,000 GEL total per year. The category split and monthly weights are model assumptions — editable.
A4: ბლოკი 1 — წლიური თანხა და თვიური წილი (%) / BLOCK 1 — annual amount and monthly weight (%)
A5: კატეგორია / Category | B5: წლიური GEL / Annual | C5: Jan / იან | D5: Feb / თებ | E5: Mar / მარ | F5: Apr / აპრ | G5: May / მაი | H5: Jun / ივნ | I5: Jul / ივლ | J5: Aug / აგვ | K5: Sep / სექ | L5: Oct / ოქტ | M5: Nov / ნოე | N5: Dec / დეკ | O5: ჯამი % / Check
A6: ხელფასები / Labour & wages | B6: 48000 | C6: 0.09 | D6: 0.09 | E6: 0.09 | F6: 0.08 | G6: 0.07 | H6: 0.09 | I6: 0.09 | J6: 0.09 | K6: 0.08 | L6: 0.07 | M6: 0.07 | N6: 0.09 | O6: =SUM(C6:N6) -> 1
A7: გათბობა (გაზი/საწვავი) / Heating (gas & fuel) | B7: 36000 | C7: 0.25 | D7: 0.22 | E7: 0.13 | F7: 0.03 | G7: 0 | H7: 0 | I7: 0 | J7: 0 | K7: 0 | L7: 0.04 | M7: 0.13 | N7: 0.2 | O7: =SUM(C7:N7) -> 1
A8: ელექტროენერგია და წყალი / Electricity & water | B8: 12000 | C8: 0.08 | D8: 0.08 | E8: 0.08 | F8: 0.08 | G8: 0.09 | H8: 0.1 | I8: 0.11 | J8: 0.11 | K8: 0.09 | L8: 0.06 | M8: 0.06 | N8: 0.06 | O8: =SUM(C8:N8) -> 1
A9: ნერგები და თესლი / Seedlings & seeds | B9: 14000 | C9: 0 | D9: 0 | E9: 0.2 | F9: 0.25 | G9: 0 | H9: 0 | I9: 0 | J9: 0.3 | K9: 0.25 | L9: 0 | M9: 0 | N9: 0 | O9: =SUM(C9:N9) -> 1
A10: სასუქი და მცენარეთა დაცვა / Fertiliser & crop protection | B10: 18000 | C10: 0.08 | D10: 0.1 | E10: 0.12 | F10: 0.1 | G10: 0.08 | H10: 0.08 | I10: 0.08 | J10: 0.08 | K10: 0.1 | L10: 0.1 | M10: 0.04 | N10: 0.04 | O10: =SUM(C10:N10) -> 1
A11: შეფუთვა და ლოგისტიკა / Packaging & logistics | B11: 10000 | C11: 0.12 | D11: 0.14 | E11: 0.14 | F11: 0.08 | G11: 0 | H11: 0.07 | I11: 0.11 | J11: 0.11 | K11: 0.07 | L11: 0 | M11: 0 | N11: 0.16 | O11: =SUM(C11:N11) -> 1
A12: რემონტი და მოვლა / Maintenance & repairs | B12: 6000 | C12: 0.02 | D12: 0.02 | E12: 0.02 | F12: 0.04 | G12: 0.2 | H12: 0.1 | I12: 0.02 | J12: 0.02 | K12: 0.03 | L12: 0.25 | M12: 0.25 | N12: 0.03 | O12: =SUM(C12:N12) -> 1
A13: ადმინისტრაცია, დაზღვევა, ბუღალტერია / Admin, insurance, accounting | B13: 6000 | C13: 0.08 | D13: 0.08 | E13: 0.09 | F13: 0.08 | G13: 0.08 | H13: 0.09 | I13: 0.08 | J13: 0.08 | K13: 0.09 | L13: 0.08 | M13: 0.08 | N13: 0.09 | O13: =SUM(C13:N13) -> 1
A14: სულ / TOTAL | B14: =SUM(B6:B13) -> 150000 | C14: =IFERROR(SUMPRODUCT($B$6:$B$13,C6:C13)/$B$14,0) -> 0.1168 | D14: =IFERROR(SUMPRODUCT($B$6:$B$13,D6:D13)/$B$14,0) -> 0.11333333 | E14: =IFERROR(SUMPRODUCT($B$6:$B$13,E6:E13)/$B$14,0) -> 0.1132 | F14: =IFERROR(SUMPRODUCT($B$6:$B$13,F6:F13)/$B$14,0) -> 0.084666667 | G14: =IFERROR(SUMPRODUCT($B$6:$B$13,G6:G13)/$B$14,0) -> 0.0504 | H14: =IFERROR(SUMPRODUCT($B$6:$B$13,H6:H13)/$B$14,0) -> 0.058666667 | I14: =IFERROR(SUMPRODUCT($B$6:$B$13,I6:I13)/$B$14,0) -> 0.058533333 | J14: =IFERROR(SUMPRODUCT($B$6:$B$13,J6:J13)/$B$14,0) -> 0.086533333 | ... N14: =IFERROR(SUMPRODUCT($B$6:$B$13,N6:N13)/$B$14,0) -> 0.10186667 | O14: =SUM(C14:N14) -> 1
A15: თითოეული სტრიქონის „ჯამი %" უნდა იყოს 100.0%. / Every row's check must read 100.0%.
A17: ბლოკი 2 — თვიური ხარჯი (GEL) / BLOCK 2 — monthly cost (GEL)
A18: კატეგორია / Category | B18: Jan / იან | C18: Feb / თებ | D18: Mar / მარ | E18: Apr / აპრ | F18: May / მაი | G18: Jun / ივნ | H18: Jul / ივლ | I18: Aug / აგვ | J18: Sep / სექ | K18: Oct / ოქტ | L18: Nov / ნოე | M18: Dec / დეკ | N18: სულ / Total
A19: ხელფასები / Labour & wages | B19: =$B$6*C6 -> 4320 | C19: =$B$6*D6 -> 4320 | D19: =$B$6*E6 -> 4320 | E19: =$B$6*F6 -> 3840 | F19: =$B$6*G6 -> 3360 | G19: =$B$6*H6 -> 4320 | H19: =$B$6*I6 -> 4320 | I19: =$B$6*J6 -> 4320 | ... M19: =$B$6*N6 -> 4320 | N19: =SUM(B19:M19) -> 48000
A20: გათბობა (გაზი/საწვავი) / Heating (gas & fuel) | B20: =$B$7*C7 -> 9000 | C20: =$B$7*D7 -> 7920 | D20: =$B$7*E7 -> 4680 | E20: =$B$7*F7 -> 1080 | F20: =$B$7*G7 -> 0 | G20: =$B$7*H7 -> 0 | H20: =$B$7*I7 -> 0 | I20: =$B$7*J7 -> 0 | ... M20: =$B$7*N7 -> 7200 | N20: =SUM(B20:M20) -> 36000
A21: ელექტროენერგია და წყალი / Electricity & water | B21: =$B$8*C8 -> 960 | C21: =$B$8*D8 -> 960 | D21: =$B$8*E8 -> 960 | E21: =$B$8*F8 -> 960 | F21: =$B$8*G8 -> 1080 | G21: =$B$8*H8 -> 1200 | H21: =$B$8*I8 -> 1320 | I21: =$B$8*J8 -> 1320 | ... M21: =$B$8*N8 -> 720 | N21: =SUM(B21:M21) -> 12000
A22: ნერგები და თესლი / Seedlings & seeds | B22: =$B$9*C9 -> 0 | C22: =$B$9*D9 -> 0 | D22: =$B$9*E9 -> 2800 | E22: =$B$9*F9 -> 3500 | F22: =$B$9*G9 -> 0 | G22: =$B$9*H9 -> 0 | H22: =$B$9*I9 -> 0 | I22: =$B$9*J9 -> 4200 | ... M22: =$B$9*N9 -> 0 | N22: =SUM(B22:M22) -> 14000
A23: სასუქი და მცენარეთა დაცვა / Fertiliser & crop protection | B23: =$B$10*C10 -> 1440 | C23: =$B$10*D10 -> 1800 | D23: =$B$10*E10 -> 2160 | E23: =$B$10*F10 -> 1800 | F23: =$B$10*G10 -> 1440 | G23: =$B$10*H10 -> 1440 | H23: =$B$10*I10 -> 1440 | I23: =$B$10*J10 -> 1440 | ... M23: =$B$10*N10 -> 720 | N23: =SUM(B23:M23) -> 18000
A24: შეფუთვა და ლოგისტიკა / Packaging & logistics | B24: =$B$11*C11 -> 1200 | C24: =$B$11*D11 -> 1400 | D24: =$B$11*E11 -> 1400 | E24: =$B$11*F11 -> 800 | F24: =$B$11*G11 -> 0 | G24: =$B$11*H11 -> 700 | H24: =$B$11*I11 -> 1100 | I24: =$B$11*J11 -> 1100 | ... M24: =$B$11*N11 -> 1600 | N24: =SUM(B24:M24) -> 10000
A25: რემონტი და მოვლა / Maintenance & repairs | B25: =$B$12*C12 -> 120 | C25: =$B$12*D12 -> 120 | D25: =$B$12*E12 -> 120 | E25: =$B$12*F12 -> 240 | F25: =$B$12*G12 -> 1200 | G25: =$B$12*H12 -> 600 | H25: =$B$12*I12 -> 120 | I25: =$B$12*J12 -> 120 | ... M25: =$B$12*N12 -> 180 | N25: =SUM(B25:M25) -> 6000
A26: ადმინისტრაცია, დაზღვევა, ბუღალტერია / Admin, insurance, accounting | B26: =$B$13*C13 -> 480 | C26: =$B$13*D13 -> 480 | D26: =$B$13*E13 -> 540 | E26: =$B$13*F13 -> 480 | F26: =$B$13*G13 -> 480 | G26: =$B$13*H13 -> 540 | H26: =$B$13*I13 -> 480 | I26: =$B$13*J13 -> 480 | ... M26: =$B$13*N13 -> 540 | N26: =SUM(B26:M26) -> 6000
A27: სულ OPEX / TOTAL OPEX | B27: =SUM(B19:B26) -> 17520 | C27: =SUM(C19:C26) -> 17000 | D27: =SUM(D19:D26) -> 16980 | E27: =SUM(E19:E26) -> 12700 | F27: =SUM(F19:F26) -> 7560 | G27: =SUM(G19:G26) -> 8800 | H27: =SUM(H19:H26) -> 8780 | I27: =SUM(I19:I26) -> 12980 | ... M27: =SUM(M19:M26) -> 15280 | N27: =SUM(B27:M27) -> 150000

Sheet Loan
A1: სესხის გრაფიკი / LOAN SCHEDULE — სს „ბანკი ქართუ" / CARTU BANK
A2: ხელშეკრულება GA/1-876787–001, 17/06/2026 · შეღავათიანი აგრო კრედიტი · ყველა პირობა ხელშეკრულებიდან / Contract GA/1-876787–001 of 17/06/2026 · preferential agro credit · every term is taken from the contract
A4: თვე / M | B4: თარიღი / Date | C4: წელი / Yr | D4: საწყისი ძირი / Opening | E4: დარიცხული % / Interest | F4: სააგენტო / Agency | G4: წმინდა % / Net interest | H4: ძირი / Principal | I4: გადახდა / Payment | J4: დარჩენილი ძირი / Closing | K4: დაგროვილი % / Accrued | M4: წელი / Yr | N4: დარიცხული % / Interest | O4: სააგენტო / Agency | P4: წმინდა % / Net interest | Q4: ძირი / Principal | R4: გადახდა / Cash paid | S4: ნაშთი წლის ბოლოს / Closing
A5: 1 | B5: =EDATE(DATE(2026,6,17),A5) -> 46220 | C5: =INT((A5-1)/12)+1 -> 1 | D5: =Assumptions!$B$29 -> 625000 | E5: =IF(A5>Assumptions!$B$31,0,D5*IF(A5<Assumptions!$B$37,Assumptions!$B$30,Assumptions!$B$36)/12) -> 6583.3333 | F5: =IF(A5>Assumptions!$B$35,0,MIN(E5,D5*Assumptions!$B$34/12)) -> 5729.1667 | G5: =E5-F5 -> 854.16667 | H5: =IF(A5>Assumptions!$B$31,0,IF(A5<=Assumptions!$B$32+1,0,MIN(D5,PMT(IF(A5<Assumptions!$B$37,Assumptions!$B$30,Assumptions!$B$36)/12,Assumptions!$B$31-A5+1,-D5)-E5))) -> 0 | I5: =IF(A5>Assumptions!$B$31,0,IF(A5<=Assumptions!$B$32,0,IF(A5=Assumptions!$B$32+1,0+G5,H5+G5))) -> 0 | J5: =D5-H5 -> 625000 | K5: =IF(A5<=Assumptions!$B$32,0+G5,0) -> 854.16667 | M5: 1 | N5: =SUMIF($C$5:$C$124,$M5,$E$5:$E$124) -> 79000 | O5: =SUMIF($C$5:$C$124,$M5,$F$5:$F$124) -> 68750 | P5: =SUMIF($C$5:$C$124,$M5,$G$5:$G$124) -> 10250 | Q5: =SUMIF($C$5:$C$124,$M5,$H$5:$H$124) -> 0 | R5: =SUMIF($C$5:$C$124,$M5,$I$5:$I$124) -> 0 | S5: =INDEX($J$5:$J$124,MATCH($M5*12,$A$5:$A$124,0)) -> 625000
A6: 2 | B6: =EDATE(DATE(2026,6,17),A6) -> 46251 | C6: =INT((A6-1)/12)+1 -> 1 | D6: =J5 -> 625000 | E6: =IF(A6>Assumptions!$B$31,0,D6*IF(A6<Assumptions!$B$37,Assumptions!$B$30,Assumptions!$B$36)/12) -> 6583.3333 | F6: =IF(A6>Assumptions!$B$35,0,MIN(E6,D6*Assumptions!$B$34/12)) -> 5729.1667 | G6: =E6-F6 -> 854.16667 | H6: =IF(A6>Assumptions!$B$31,0,IF(A6<=Assumptions!$B$32+1,0,MIN(D6,PMT(IF(A6<Assumptions!$B$37,Assumptions!$B$30,Assumptions!$B$36)/12,Assumptions!$B$31-A6+1,-D6)-E6))) -> 0 | I6: =IF(A6>Assumptions!$B$31,0,IF(A6<=Assumptions!$B$32,0,IF(A6=Assumptions!$B$32+1,K5+G6,H6+G6))) -> 0 | J6: =D6-H6 -> 625000 | K6: =IF(A6<=Assumptions!$B$32,K5+G6,0) -> 1708.3333 | M6: 2 | N6: =SUMIF($C$5:$C$124,$M6,$E$5:$E$124) -> 77471.314 | O6: =SUMIF($C$5:$C$124,$M6,$F$5:$F$124) -> 67093.578 | P6: =SUMIF($C$5:$C$124,$M6,$G$5:$G$124) -> 10377.736 | Q6: =SUMIF($C$5:$C$124,$M6,$H$5:$H$124) -> 36790.995 | R6: =SUMIF($C$5:$C$124,$M6,$I$5:$I$124) -> 57418.731 | S6: =INDEX($J$5:$J$124,MATCH($M6*12,$A$5:$A$124,0)) -> 588209.01
A7: 3 | B7: =EDATE(DATE(2026,6,17),A7) -> 46282 | C7: =INT((A7-1)/12)+1 -> 1 | D7: =J6 -> 625000 | E7: =IF(A7>Assumptions!$B$31,0,D7*IF(A7<Assumptions!$B$37,Assumptions!$B$30,Assumptions!$B$36)/12) -> 6583.3333 | F7: =IF(A7>Assumptions!$B$35,0,MIN(E7,D7*Assumptions!$B$34/12)) -> 5729.1667 | G7: =E7-F7 -> 854.16667 | H7: =IF(A7>Assumptions!$B$31,0,IF(A7<=Assumptions!$B$32+1,0,MIN(D7,PMT(IF(A7<Assumptions!$B$37,Assumptions!$B$30,Assumptions!$B$36)/12,Assumptions!$B$31-A7+1,-D7)-E7))) -> 0 | I7: =IF(A7>Assumptions!$B$31,0,IF(A7<=Assumptions!$B$32,0,IF(A7=Assumptions!$B$32+1,K6+G7,H7+G7))) -> 0 | J7: =D7-H7 -> 625000 | K7: =IF(A7<=Assumptions!$B$32,K6+G7,0) -> 2562.5 | M7: 3 | N7: =SUMIF($C$5:$C$124,$M7,$E$5:$E$124) -> 76180.358 | O7: =SUMIF($C$5:$C$124,$M7,$F$5:$F$124) -> 62536.115 | P7: =SUMIF($C$5:$C$124,$M7,$G$5:$G$124) -> 13644.243 | Q7: =SUMIF($C$5:$C$124,$M7,$H$5:$H$124) -> 44038.62 | R7: =SUMIF($C$5:$C$124,$M7,$I$5:$I$124) -> 57682.864 | S7: =INDEX($J$5:$J$124,MATCH($M7*12,$A$5:$A$124,0)) -> 544170.38
A8: 4 | B8: =EDATE(DATE(2026,6,17),A8) -> 46312 | C8: =INT((A8-1)/12)+1 -> 1 | D8: =J7 -> 625000 | E8: =IF(A8>Assumptions!$B$31,0,D8*IF(A8<Assumptions!$B$37,Assumptions!$B$30,Assumptions!$B$36)/12) -> 6583.3333 | F8: =IF(A8>Assumptions!$B$35,0,MIN(E8,D8*Assumptions!$B$34/12)) -> 5729.1667 | G8: =E8-F8 -> 854.16667 | H8: =IF(A8>Assumptions!$B$31,0,IF(A8<=Assumptions!$B$32+1,0,MIN(D8,PMT(IF(A8<Assumptions!$B$37,Assumptions!$B$30,Assumptions!$B$36)/12,Assumptions!$B$31-A8+1,-D8)-E8))) -> 0 | I8: =IF(A8>Assumptions!$B$31,0,IF(A8<=Assumptions!$B$32,0,IF(A8=Assumptions!$B$32+1,K7+G8,H8+G8))) -> 0 | J8: =D8-H8 -> 625000 | K8: =IF(A8<=Assumptions!$B$32,K7+G8,0) -> 3416.6667 | M8: 4 | N8: =SUMIF($C$5:$C$124,$M8,$E$5:$E$124) -> 69902.917 | O8: =SUMIF($C$5:$C$124,$M8,$F$5:$F$124) -> 57382.992 | P8: =SUMIF($C$5:$C$124,$M8,$G$5:$G$124) -> 12519.925 | Q8: =SUMIF($C$5:$C$124,$M8,$H$5:$H$124) -> 50316.062 | R8: =SUMIF($C$5:$C$124,$M8,$I$5:$I$124) -> 62835.987 | S8: =INDEX($J$5:$J$124,MATCH($M8*12,$A$5:$A$124,0)) -> 493854.32
A9: 5 | B9: =EDATE(DATE(2026,6,17),A9) -> 46343 | C9: =INT((A9-1)/12)+1 -> 1 | D9: =J8 -> 625000 | E9: =IF(A9>Assumptions!$B$31,0,D9*IF(A9<Assumptions!$B$37,Assumptions!$B$30,Assumptions!$B$36)/12) -> 6583.3333 | F9: =IF(A9>Assumptions!$B$35,0,MIN(E9,D9*Assumptions!$B$34/12)) -> 5729.1667 | G9: =E9-F9 -> 854.16667 | H9: =IF(A9>Assumptions!$B$31,0,IF(A9<=Assumptions!$B$32+1,0,MIN(D9,PMT(IF(A9<Assumptions!$B$37,Assumptions!$B$30,Assumptions!$B$36)/12,Assumptions!$B$31-A9+1,-D9)-E9))) -> 0 | I9: =IF(A9>Assumptions!$B$31,0,IF(A9<=Assumptions!$B$32,0,IF(A9=Assumptions!$B$32+1,K8+G9,H9+G9))) -> 0 | J9: =D9-H9 -> 625000 | K9: =IF(A9<=Assumptions!$B$32,K8+G9,0) -> 4270.8333 | M9: 5 | N9: =SUMIF($C$5:$C$124,$M9,$E$5:$E$124) -> 62730.664 | O9: =SUMIF($C$5:$C$124,$M9,$F$5:$F$124) -> 0 | P9: =SUMIF($C$5:$C$124,$M9,$G$5:$G$124) -> 62730.664 | Q9: =SUMIF($C$5:$C$124,$M9,$H$5:$H$124) -> 57488.314 | R9: =SUMIF($C$5:$C$124,$M9,$I$5:$I$124) -> 120218.98 | S9: =INDEX($J$5:$J$124,MATCH($M9*12,$A$5:$A$124,0)) -> 436366.01
A10: 6 | B10: =EDATE(DATE(2026,6,17),A10) -> 46373 | C10: =INT((A10-1)/12)+1 -> 1 | D10: =J9 -> 625000 | E10: =IF(A10>Assumptions!$B$31,0,D10*IF(A10<Assumptions!$B$37,Assumptions!$B$30,Assumptions!$B$36)/12) -> 6583.3333 | F10: =IF(A10>Assumptions!$B$35,0,MIN(E10,D10*Assumptions!$B$34/12)) -> 5729.1667 | G10: =E10-F10 -> 854.16667 | H10: =IF(A10>Assumptions!$B$31,0,IF(A10<=Assumptions!$B$32+1,0,MIN(D10,PMT(IF(A10<Assumptions!$B$37,Assumptions!$B$30,Assumptions!$B$36)/12,Assumptions!$B$31-A10+1,-D10)-E10))) -> 0 | I10: =IF(A10>Assumptions!$B$31,0,IF(A10<=Assumptions!$B$32,0,IF(A10=Assumptions!$B$32+1,K9+G10,H10+G10))) -> 0 | J10: =D10-H10 -> 625000 | K10: =IF(A10<=Assumptions!$B$32,K9+G10,0) -> 5125 | M10: 6 | N10: =SUMIF($C$5:$C$124,$M10,$E$5:$E$124) -> 54536.05 | O10: =SUMIF($C$5:$C$124,$M10,$F$5:$F$124) -> 0 | P10: =SUMIF($C$5:$C$124,$M10,$G$5:$G$124) -> 54536.05 | Q10: =SUMIF($C$5:$C$124,$M10,$H$5:$H$124) -> 65682.929 | R10: =SUMIF($C$5:$C$124,$M10,$I$5:$I$124) -> 120218.98 | S10: =INDEX($J$5:$J$124,MATCH($M10*12,$A$5:$A$124,0)) -> 370683.08
A11: 7 | B11: =EDATE(DATE(2026,6,17),A11) -> 46404 | C11: =INT((A11-1)/12)+1 -> 1 | D11: =J10 -> 625000 | E11: =IF(A11>Assumptions!$B$31,0,D11*IF(A11<Assumptions!$B$37,Assumptions!$B$30,Assumptions!$B$36)/12) -> 6583.3333 | F11: =IF(A11>Assumptions!$B$35,0,MIN(E11,D11*Assumptions!$B$34/12)) -> 5729.1667 | G11: =E11-F11 -> 854.16667 | H11: =IF(A11>Assumptions!$B$31,0,IF(A11<=Assumptions!$B$32+1,0,MIN(D11,PMT(IF(A11<Assumptions!$B$37,Assumptions!$B$30,Assumptions!$B$36)/12,Assumptions!$B$31-A11+1,-D11)-E11))) -> 0 | I11: =IF(A11>Assumptions!$B$31,0,IF(A11<=Assumptions!$B$32,0,IF(A11=Assumptions!$B$32+1,K10+G11,H11+G11))) -> 0 | J11: =D11-H11 -> 625000 | K11: =IF(A11<=Assumptions!$B$32,K10+G11,0) -> 5979.1667 | M11: 7 | N11: =SUMIF($C$5:$C$124,$M11,$E$5:$E$124) -> 45173.342 | O11: =SUMIF($C$5:$C$124,$M11,$F$5:$F$124) -> 0 | P11: =SUMIF($C$5:$C$124,$M11,$G$5:$G$124) -> 45173.342 | Q11: =SUMIF($C$5:$C$124,$M11,$H$5:$H$124) -> 75045.636 | R11: =SUMIF($C$5:$C$124,$M11,$I$5:$I$124) -> 120218.98 | S11: =INDEX($J$5:$J$124,MATCH($M11*12,$A$5:$A$124,0)) -> 295637.44
A12: 8 | B12: =EDATE(DATE(2026,6,17),A12) -> 46435 | C12: =INT((A12-1)/12)+1 -> 1 | D12: =J11 -> 625000 | E12: =IF(A12>Assumptions!$B$31,0,D12*IF(A12<Assumptions!$B$37,Assumptions!$B$30,Assumptions!$B$36)/12) -> 6583.3333 | F12: =IF(A12>Assumptions!$B$35,0,MIN(E12,D12*Assumptions!$B$34/12)) -> 5729.1667 | G12: =E12-F12 -> 854.16667 | H12: =IF(A12>Assumptions!$B$31,0,IF(A12<=Assumptions!$B$32+1,0,MIN(D12,PMT(IF(A12<Assumptions!$B$37,Assumptions!$B$30,Assumptions!$B$36)/12,Assumptions!$B$31-A12+1,-D12)-E12))) -> 0 | I12: =IF(A12>Assumptions!$B$31,0,IF(A12<=Assumptions!$B$32,0,IF(A12=Assumptions!$B$32+1,K11+G12,H12+G12))) -> 0 | J12: =D12-H12 -> 625000 | K12: =IF(A12<=Assumptions!$B$32,K11+G12,0) -> 6833.3333 | M12: 8 | N12: =SUMIF($C$5:$C$124,$M12,$E$5:$E$124) -> 34476.037 | O12: =SUMIF($C$5:$C$124,$M12,$F$5:$F$124) -> 0 | P12: =SUMIF($C$5:$C$124,$M12,$G$5:$G$124) -> 34476.037 | Q12: =SUMIF($C$5:$C$124,$M12,$H$5:$H$124) -> 85742.942 | R12: =SUMIF($C$5:$C$124,$M12,$I$5:$I$124) -> 120218.98 | S12: =INDEX($J$5:$J$124,MATCH($M12*12,$A$5:$A$124,0)) -> 209894.5
A13: 9 | B13: =EDATE(DATE(2026,6,17),A13) -> 46463 | C13: =INT((A13-1)/12)+1 -> 1 | D13: =J12 -> 625000 | E13: =IF(A13>Assumptions!$B$31,0,D13*IF(A13<Assumptions!$B$37,Assumptions!$B$30,Assumptions!$B$36)/12) -> 6583.3333 | F13: =IF(A13>Assumptions!$B$35,0,MIN(E13,D13*Assumptions!$B$34/12)) -> 5729.1667 | G13: =E13-F13 -> 854.16667 | H13: =IF(A13>Assumptions!$B$31,0,IF(A13<=Assumptions!$B$32+1,0,MIN(D13,PMT(IF(A13<Assumptions!$B$37,Assumptions!$B$30,Assumptions!$B$36)/12,Assumptions!$B$31-A13+1,-D13)-E13))) -> 0 | I13: =IF(A13>Assumptions!$B$31,0,IF(A13<=Assumptions!$B$32,0,IF(A13=Assumptions!$B$32+1,K12+G13,H13+G13))) -> 0 | J13: =D13-H13 -> 625000 | K13: =IF(A13<=Assumptions!$B$32,K12+G13,0) -> 7687.5 | M13: 9 | N13: =SUMIF($C$5:$C$124,$M13,$E$5:$E$124) -> 22253.895 | O13: =SUMIF($C$5:$C$124,$M13,$F$5:$F$124) -> 0 | P13: =SUMIF($C$5:$C$124,$M13,$G$5:$G$124) -> 22253.895 | Q13: =SUMIF($C$5:$C$124,$M13,$H$5:$H$124) -> 97965.084 | R13: =SUMIF($C$5:$C$124,$M13,$I$5:$I$124) -> 120218.98 | S13: =INDEX($J$5:$J$124,MATCH($M13*12,$A$5:$A$124,0)) -> 111929.42
A14: 10 | B14: =EDATE(DATE(2026,6,17),A14) -> 46494 | C14: =INT((A14-1)/12)+1 -> 1 | D14: =J13 -> 625000 | E14: =IF(A14>Assumptions!$B$31,0,D14*IF(A14<Assumptions!$B$37,Assumptions!$B$30,Assumptions!$B$36)/12) -> 6583.3333 | F14: =IF(A14>Assumptions!$B$35,0,MIN(E14,D14*Assumptions!$B$34/12)) -> 5729.1667 | G14: =E14-F14 -> 854.16667 | H14: =IF(A14>Assumptions!$B$31,0,IF(A14<=Assumptions!$B$32+1,0,MIN(D14,PMT(IF(A14<Assumptions!$B$37,Assumptions!$B$30,Assumptions!$B$36)/12,Assumptions!$B$31-A14+1,-D14)-E14))) -> 0 | I14: =IF(A14>Assumptions!$B$31,0,IF(A14<=Assumptions!$B$32,0,IF(A14=Assumptions!$B$32+1,K13+G14,H14+G14))) -> 0 | J14: =D14-H14 -> 625000 | K14: =IF(A14<=Assumptions!$B$32,K13+G14,0) -> 8541.6667 | M14: 10 | N14: =SUMIF($C$5:$C$124,$M14,$E$5:$E$124) -> 8289.5599 | O14: =SUMIF($C$5:$C$124,$M14,$F$5:$F$124) -> 0 | P14: =SUMIF($C$5:$C$124,$M14,$G$5:$G$124) -> 8289.5599 | Q14: =SUMIF($C$5:$C$124,$M14,$H$5:$H$124) -> 111929.42 | R14: =SUMIF($C$5:$C$124,$M14,$I$5:$I$124) -> 120218.98 | S14: =INDEX($J$5:$J$124,MATCH($M14*12,$A$5:$A$124,0)) -> 8.9130481e-11
A15: 11 | B15: =EDATE(DATE(2026,6,17),A15) -> 46524 | C15: =INT((A15-1)/12)+1 -> 1 | D15: =J14 -> 625000 | E15: =IF(A15>Assumptions!$B$31,0,D15*IF(A15<Assumptions!$B$37,Assumptions!$B$30,Assumptions!$B$36)/12) -> 6583.3333 | F15: =IF(A15>Assumptions!$B$35,0,MIN(E15,D15*Assumptions!$B$34/12)) -> 5729.1667 | G15: =E15-F15 -> 854.16667 | H15: =IF(A15>Assumptions!$B$31,0,IF(A15<=Assumptions!$B$32+1,0,MIN(D15,PMT(IF(A15<Assumptions!$B$37,Assumptions!$B$30,Assumptions!$B$36)/12,Assumptions!$B$31-A15+1,-D15)-E15))) -> 0 | I15: =IF(A15>Assumptions!$B$31,0,IF(A15<=Assumptions!$B$32,0,IF(A15=Assumptions!$B$32+1,K14+G15,H15+G15))) -> 0 | J15: =D15-H15 -> 625000 | K15: =IF(A15<=Assumptions!$B$32,K14+G15,0) -> 9395.8333 | M15: სულ / TOTAL | N15: =SUM(N5:N14) -> 530014.14 | O15: =SUM(O5:O14) -> 255762.68 | P15: =SUM(P5:P14) -> 274251.45 | Q15: =SUM(Q5:Q14) -> 625000 | R15: =SUM(R5:R14) -> 899251.45
A16: 12 | B16: =EDATE(DATE(2026,6,17),A16) -> 46555 | C16: =INT((A16-1)/12)+1 -> 1 | D16: =J15 -> 625000 | E16: =IF(A16>Assumptions!$B$31,0,D16*IF(A16<Assumptions!$B$37,Assumptions!$B$30,Assumptions!$B$36)/12) -> 6583.3333 | F16: =IF(A16>Assumptions!$B$35,0,MIN(E16,D16*Assumptions!$B$34/12)) -> 5729.1667 | G16: =E16-F16 -> 854.16667 | H16: =IF(A16>Assumptions!$B$31,0,IF(A16<=Assumptions!$B$32+1,0,MIN(D16,PMT(IF(A16<Assumptions!$B$37,Assumptions!$B$30,Assumptions!$B$36)/12,Assumptions!$B$31-A16+1,-D16)-E16))) -> 0 | I16: =IF(A16>Assumptions!$B$31,0,IF(A16<=Assumptions!$B$32,0,IF(A16=Assumptions!$B$32+1,K15+G16,H16+G16))) -> 0 | J16: =D16-H16 -> 625000 | K16: =IF(A16<=Assumptions!$B$32,K15+G16,0) -> 10250
A17: 13 | B17: =EDATE(DATE(2026,6,17),A17) -> 46585 | C17: =INT((A17-1)/12)+1 -> 2 | D17: =J16 -> 625000 | E17: =IF(A17>Assumptions!$B$31,0,D17*IF(A17<Assumptions!$B$37,Assumptions!$B$30,Assumptions!$B$36)/12) -> 6583.3333 | F17: =IF(A17>Assumptions!$B$35,0,MIN(E17,D17*Assumptions!$B$34/12)) -> 5729.1667 | G17: =E17-F17 -> 854.16667 | H17: =IF(A17>Assumptions!$B$31,0,IF(A17<=Assumptions!$B$32+1,0,MIN(D17,PMT(IF(A17<Assumptions!$B$37,Assumptions!$B$30,Assumptions!$B$36)/12,Assumptions!$B$31-A17+1,-D17)-E17))) -> 0 | I17: =IF(A17>Assumptions!$B$31,0,IF(A17<=Assumptions!$B$32,0,IF(A17=Assumptions!$B$32+1,K16+G17,H17+G17))) -> 11104.167 | J17: =D17-H17 -> 625000 | K17: =IF(A17<=Assumptions!$B$32,K16+G17,0) -> 0 | M17: შედარება ბანკის გრაფიკთან (დანართი #1) / CROSS-CHECK vs THE BANK'S OWN SCHEDULE
A18: 14 | B18: =EDATE(DATE(2026,6,17),A18) -> 46616 | C18: =INT((A18-1)/12)+1 -> 2 | D18: =J17 -> 625000 | E18: =IF(A18>Assumptions!$B$31,0,D18*IF(A18<Assumptions!$B$37,Assumptions!$B$30,Assumptions!$B$36)/12) -> 6583.3333 | F18: =IF(A18>Assumptions!$B$35,0,MIN(E18,D18*Assumptions!$B$34/12)) -> 5729.1667 | G18: =E18-F18 -> 854.16667 | H18: =IF(A18>Assumptions!$B$31,0,IF(A18<=Assumptions!$B$32+1,0,MIN(D18,PMT(IF(A18<Assumptions!$B$37,Assumptions!$B$30,Assumptions!$B$36)/12,Assumptions!$B$31-A18+1,-D18)-E18))) -> 3182.7394 | I18: =IF(A18>Assumptions!$B$31,0,IF(A18<=Assumptions!$B$32,0,IF(A18=Assumptions!$B$32+1,K17+G18,H18+G18))) -> 4036.9061 | J18: =D18-H18 -> 621817.26 | K18: =IF(A18<=Assumptions!$B$32,K17+G18,0) -> 0 | M18: მაჩვენებელი / Item | P18: ბანკის გრაფიკი / Bank | Q18: მოდელი / Model | R18: სხვაობა / Diff
A19: 15 | B19: =EDATE(DATE(2026,6,17),A19) -> 46647 | C19: =INT((A19-1)/12)+1 -> 2 | D19: =J18 -> 621817.26 | E19: =IF(A19>Assumptions!$B$31,0,D19*IF(A19<Assumptions!$B$37,Assumptions!$B$30,Assumptions!$B$36)/12) -> 6549.8085 | F19: =IF(A19>Assumptions!$B$35,0,MIN(E19,D19*Assumptions!$B$34/12)) -> 5699.9916 | G19: =E19-F19 -> 849.81692 | H19: =IF(A19>Assumptions!$B$31,0,IF(A19<=Assumptions!$B$32+1,0,MIN(D19,PMT(IF(A19<Assumptions!$B$37,Assumptions!$B$30,Assumptions!$B$36)/12,Assumptions!$B$31-A19+1,-D19)-E19))) -> 3216.2643 | I19: =IF(A19>Assumptions!$B$31,0,IF(A19<=Assumptions!$B$32,0,IF(A19=Assumptions!$B$32+1,K18+G19,H19+G19))) -> 4066.0812 | J19: =D19-H19 -> 618601 | K19: =IF(A19<=Assumptions!$B$32,K18+G19,0) -> 0 | M19: სულ ძირი / Total principal | P19: 625000 | Q19: =H125 -> 625000 | R19: =Q19-P19 -> 2.3283064e-10
A20: 16 | B20: =EDATE(DATE(2026,6,17),A20) -> 46677 | C20: =INT((A20-1)/12)+1 -> 2 | D20: =J19 -> 618601 | E20: =IF(A20>Assumptions!$B$31,0,D20*IF(A20<Assumptions!$B$37,Assumptions!$B$30,Assumptions!$B$36)/12) -> 6515.9305 | F20: =IF(A20>Assumptions!$B$35,0,MIN(E20,D20*Assumptions!$B$34/12)) -> 5670.5091 | G20: =E20-F20 -> 845.42136 | H20: =IF(A20>Assumptions!$B$31,0,IF(A20<=Assumptions!$B$32+1,0,MIN(D20,PMT(IF(A20<Assumptions!$B$37,Assumptions!$B$30,Assumptions!$B$36)/12,Assumptions!$B$31-A20+1,-D20)-E20))) -> 3250.1422 | I20: =IF(A20>Assumptions!$B$31,0,IF(A20<=Assumptions!$B$32,0,IF(A20=Assumptions!$B$32+1,K19+G20,H20+G20))) -> 4095.5636 | J20: =D20-H20 -> 615350.85 | K20: =IF(A20<=Assumptions!$B$32,K19+G20,0) -> 0 | M20: სულ პროცენტი / Total interest | P20: 529681.25 | Q20: =E125 -> 530014.14 | R20: =Q20-P20 -> 332.88777
A21: 17 | B21: =EDATE(DATE(2026,6,17),A21) -> 46708 | C21: =INT((A21-1)/12)+1 -> 2 | D21: =J20 -> 615350.85 | E21: =IF(A21>Assumptions!$B$31,0,D21*IF(A21<Assumptions!$B$37,Assumptions!$B$30,Assumptions!$B$36)/12) -> 6481.6957 | F21: =IF(A21>Assumptions!$B$35,0,MIN(E21,D21*Assumptions!$B$34/12)) -> 5640.7162 | G21: =E21-F21 -> 840.9795 | H21: =IF(A21>Assumptions!$B$31,0,IF(A21<=Assumptions!$B$32+1,0,MIN(D21,PMT(IF(A21<Assumptions!$B$37,Assumptions!$B$30,Assumptions!$B$36)/12,Assumptions!$B$31-A21+1,-D21)-E21))) -> 3284.3771 | I21: =IF(A21>Assumptions!$B$31,0,IF(A21<=Assumptions!$B$32,0,IF(A21=Assumptions!$B$32+1,K20+G21,H21+G21))) -> 4125.3566 | J21: =D21-H21 -> 612066.48 | K21: =IF(A21<=Assumptions!$B$32,K20+G21,0) -> 0 | M21: სულ გადასახდელი / Total repayable | P21: 1154681.2 | Q21: =Q19+Q20 -> 1155014.1 | R21: =Q21-P21 -> 332.88777
A22: 18 | B22: =EDATE(DATE(2026,6,17),A22) -> 46738 | C22: =INT((A22-1)/12)+1 -> 2 | D22: =J21 -> 612066.48 | E22: =IF(A22>Assumptions!$B$31,0,D22*IF(A22<Assumptions!$B$37,Assumptions!$B$30,Assumptions!$B$36)/12) -> 6447.1002 | F22: =IF(A22>Assumptions!$B$35,0,MIN(E22,D22*Assumptions!$B$34/12)) -> 5610.6094 | G22: =E22-F22 -> 836.49085 | H22: =IF(A22>Assumptions!$B$31,0,IF(A22<=Assumptions!$B$32+1,0,MIN(D22,PMT(IF(A22<Assumptions!$B$37,Assumptions!$B$30,Assumptions!$B$36)/12,Assumptions!$B$31-A22+1,-D22)-E22))) -> 3318.9725 | I22: =IF(A22>Assumptions!$B$31,0,IF(A22<=Assumptions!$B$32,0,IF(A22=Assumptions!$B$32+1,K21+G22,H22+G22))) -> 4155.4634 | J22: =D22-H22 -> 608747.5 | K22: =IF(A22<=Assumptions!$B$32,K21+G22,0) -> 0 | M22: ბანკის გრაფიკი დანართ #1-ში 1,000-ზეა დაყვანილი (სულ ძირი 1,000.00, პროცენტი 847.49, ჯამი 1,847.49); აქ გამრავლებულია 625-ზე, რადგან კრედიტი 625,000 ლარია. / The bank's Annex 1 is stated per 1,000 units (principal 1,000.00, interest 847.49, total 1,847.49); these are scaled by 625 for the 625,000 GEL credit.
A23: 19 | B23: =EDATE(DATE(2026,6,17),A23) -> 46769 | C23: =INT((A23-1)/12)+1 -> 2 | D23: =J22 -> 608747.5 | E23: =IF(A23>Assumptions!$B$31,0,D23*IF(A23<Assumptions!$B$37,Assumptions!$B$30,Assumptions!$B$36)/12) -> 6412.1404 | F23: =IF(A23>Assumptions!$B$35,0,MIN(E23,D23*Assumptions!$B$34/12)) -> 5580.1855 | G23: =E23-F23 -> 831.95492 | H23: =IF(A23>Assumptions!$B$31,0,IF(A23<=Assumptions!$B$32+1,0,MIN(D23,PMT(IF(A23<Assumptions!$B$37,Assumptions!$B$30,Assumptions!$B$36)/12,Assumptions!$B$31-A23+1,-D23)-E23))) -> 3353.9324 | I23: =IF(A23>Assumptions!$B$31,0,IF(A23<=Assumptions!$B$32,0,IF(A23=Assumptions!$B$32+1,K22+G23,H23+G23))) -> 4185.8873 | J23: =D23-H23 -> 605393.57 | K23: =IF(A23<=Assumptions!$B$32,K22+G23,0) -> 0 | M23: სხვაობა მცირეა, რადგან ბანკი დღეების მიხედვით ითვლის, მოდელი კი თანაბარ თვეებზე. / A small difference is expected: the bank accrues on actual days, the model on equal months.
A24: 20 | B24: =EDATE(DATE(2026,6,17),A24) -> 46800 | C24: =INT((A24-1)/12)+1 -> 2 | D24: =J23 -> 605393.57 | E24: =IF(A24>Assumptions!$B$31,0,D24*IF(A24<Assumptions!$B$37,Assumptions!$B$30,Assumptions!$B$36)/12) -> 6376.8123 | F24: =IF(A24>Assumptions!$B$35,0,MIN(E24,D24*Assumptions!$B$34/12)) -> 5549.4411 | G24: =E24-F24 -> 827.37122 | H24: =IF(A24>Assumptions!$B$31,0,IF(A24<=Assumptions!$B$32+1,0,MIN(D24,PMT(IF(A24<Assumptions!$B$37,Assumptions!$B$30,Assumptions!$B$36)/12,Assumptions!$B$31-A24+1,-D24)-E24))) -> 3389.2604 | I24: =IF(A24>Assumptions!$B$31,0,IF(A24<=Assumptions!$B$32,0,IF(A24=Assumptions!$B$32+1,K23+G24,H24+G24))) -> 4216.6317 | J24: =D24-H24 -> 602004.31 | K24: =IF(A24<=Assumptions!$B$32,K23+G24,0) -> 0
A25: 21 | B25: =EDATE(DATE(2026,6,17),A25) -> 46829 | C25: =INT((A25-1)/12)+1 -> 2 | D25: =J24 -> 602004.31 | E25: =IF(A25>Assumptions!$B$31,0,D25*IF(A25<Assumptions!$B$37,Assumptions!$B$30,Assumptions!$B$36)/12) -> 6341.1121 | F25: =IF(A25>Assumptions!$B$35,0,MIN(E25,D25*Assumptions!$B$34/12)) -> 5518.3729 | G25: =E25-F25 -> 822.73923 | H25: =IF(A25>Assumptions!$B$31,0,IF(A25<=Assumptions!$B$32+1,0,MIN(D25,PMT(IF(A25<Assumptions!$B$37,Assumptions!$B$30,Assumptions!$B$36)/12,Assumptions!$B$31-A25+1,-D25)-E25))) -> 3424.9607 | I25: =IF(A25>Assumptions!$B$31,0,IF(A25<=Assumptions!$B$32,0,IF(A25=Assumptions!$B$32+1,K24+G25,H25+G25))) -> 4247.6999 | J25: =D25-H25 -> 598579.35 | K25: =IF(A25<=Assumptions!$B$32,K24+G25,0) -> 0 | M25: ანუიტეტი 1 (17/06/2028-მდე) / Annuity 1 | N25: =H18+E18 -> 9766.0727 | O25: ბანკის გრაფიკი / bank: 9,768.75
A26: 22 | B26: =EDATE(DATE(2026,6,17),A26) -> 46860 | C26: =INT((A26-1)/12)+1 -> 2 | D26: =J25 -> 598579.35 | E26: =IF(A26>Assumptions!$B$31,0,D26*IF(A26<Assumptions!$B$37,Assumptions!$B$30,Assumptions!$B$36)/12) -> 6305.0358 | F26: =IF(A26>Assumptions!$B$35,0,MIN(E26,D26*Assumptions!$B$34/12)) -> 5486.9774 | G26: =E26-F26 -> 818.05845 | H26: =IF(A26>Assumptions!$B$31,0,IF(A26<=Assumptions!$B$32+1,0,MIN(D26,PMT(IF(A26<Assumptions!$B$37,Assumptions!$B$30,Assumptions!$B$36)/12,Assumptions!$B$31-A26+1,-D26)-E26))) -> 3461.0369 | I26: =IF(A26>Assumptions!$B$31,0,IF(A26<=Assumptions!$B$32,0,IF(A26=Assumptions!$B$32+1,K25+G26,H26+G26))) -> 4279.0954 | J26: =D26-H26 -> 595118.31 | K26: =IF(A26<=Assumptions!$B$32,K25+G26,0) -> 0 | M26: ანუიტეტი 2 (17/06/2028-ის შემდეგ) / Annuity 2 | N26: =H28+E28 -> 10018.248 | O26: ბანკის გრაფიკი / bank: 10,012.50
A27: 23 | B27: =EDATE(DATE(2026,6,17),A27) -> 46890 | C27: =INT((A27-1)/12)+1 -> 2 | D27: =J26 -> 595118.31 | E27: =IF(A27>Assumptions!$B$31,0,D27*IF(A27<Assumptions!$B$37,Assumptions!$B$30,Assumptions!$B$36)/12) -> 6268.5796 | F27: =IF(A27>Assumptions!$B$35,0,MIN(E27,D27*Assumptions!$B$34/12)) -> 5455.2512 | G27: =E27-F27 -> 813.32836 | H27: =IF(A27>Assumptions!$B$31,0,IF(A27<=Assumptions!$B$32+1,0,MIN(D27,PMT(IF(A27<Assumptions!$B$37,Assumptions!$B$30,Assumptions!$B$36)/12,Assumptions!$B$31-A27+1,-D27)-E27))) -> 3497.4932 | I27: =IF(A27>Assumptions!$B$31,0,IF(A27<=Assumptions!$B$32,0,IF(A27=Assumptions!$B$32+1,K26+G27,H27+G27))) -> 4310.8215 | J27: =D27-H27 -> 591620.82 | K27: =IF(A27<=Assumptions!$B$32,K26+G27,0) -> 0
A28: 24 | B28: =EDATE(DATE(2026,6,17),A28) -> 46921 | C28: =INT((A28-1)/12)+1 -> 2 | D28: =J27 -> 591620.82 | E28: =IF(A28>Assumptions!$B$31,0,D28*IF(A28<Assumptions!$B$37,Assumptions!$B$30,Assumptions!$B$36)/12) -> 6606.4325 | F28: =IF(A28>Assumptions!$B$35,0,MIN(E28,D28*Assumptions!$B$34/12)) -> 5423.1909 | G28: =E28-F28 -> 1183.2416 | H28: =IF(A28>Assumptions!$B$31,0,IF(A28<=Assumptions!$B$32+1,0,MIN(D28,PMT(IF(A28<Assumptions!$B$37,Assumptions!$B$30,Assumptions!$B$36)/12,Assumptions!$B$31-A28+1,-D28)-E28))) -> 3411.8157 | I28: =IF(A28>Assumptions!$B$31,0,IF(A28<=Assumptions!$B$32,0,IF(A28=Assumptions!$B$32+1,K27+G28,H28+G28))) -> 4595.0574 | J28: =D28-H28 -> 588209.01 | K28: =IF(A28<=Assumptions!$B$32,K27+G28,0) -> 0 | M28: წყარო: Mukrlhranis loan contract, GA/1-876787–001 (Google Drive) / Source: the signed contract on Drive
A29: 25 | B29: =EDATE(DATE(2026,6,17),A29) -> 46951 | C29: =INT((A29-1)/12)+1 -> 3 | D29: =J28 -> 588209.01 | E29: =IF(A29>Assumptions!$B$31,0,D29*IF(A29<Assumptions!$B$37,Assumptions!$B$30,Assumptions!$B$36)/12) -> 6568.3339 | F29: =IF(A29>Assumptions!$B$35,0,MIN(E29,D29*Assumptions!$B$34/12)) -> 5391.9159 | G29: =E29-F29 -> 1176.418 | H29: =IF(A29>Assumptions!$B$31,0,IF(A29<=Assumptions!$B$32+1,0,MIN(D29,PMT(IF(A29<Assumptions!$B$37,Assumptions!$B$30,Assumptions!$B$36)/12,Assumptions!$B$31-A29+1,-D29)-E29))) -> 3449.9143 | I29: =IF(A29>Assumptions!$B$31,0,IF(A29<=Assumptions!$B$32,0,IF(A29=Assumptions!$B$32+1,K28+G29,H29+G29))) -> 4626.3323 | J29: =D29-H29 -> 584759.09 | K29: =IF(A29<=Assumptions!$B$32,K28+G29,0) -> 0
A30: 26 | B30: =EDATE(DATE(2026,6,17),A30) -> 46982 | C30: =INT((A30-1)/12)+1 -> 3 | D30: =J29 -> 584759.09 | E30: =IF(A30>Assumptions!$B$31,0,D30*IF(A30<Assumptions!$B$37,Assumptions!$B$30,Assumptions!$B$36)/12) -> 6529.8098 | F30: =IF(A30>Assumptions!$B$35,0,MIN(E30,D30*Assumptions!$B$34/12)) -> 5360.2917 | G30: =E30-F30 -> 1169.5182 | H30: =IF(A30>Assumptions!$B$31,0,IF(A30<=Assumptions!$B$32+1,0,MIN(D30,PMT(IF(A30<Assumptions!$B$37,Assumptions!$B$30,Assumptions!$B$36)/12,Assumptions!$B$31-A30+1,-D30)-E30))) -> 3488.4384 | I30: =IF(A30>Assumptions!$B$31,0,IF(A30<=Assumptions!$B$32,0,IF(A30=Assumptions!$B$32+1,K29+G30,H30+G30))) -> 4657.9566 | J30: =D30-H30 -> 581270.65 | K30: =IF(A30<=Assumptions!$B$32,K29+G30,0) -> 0
A31: 27 | B31: =EDATE(DATE(2026,6,17),A31) -> 47013 | C31: =INT((A31-1)/12)+1 -> 3 | D31: =J30 -> 581270.65 | E31: =IF(A31>Assumptions!$B$31,0,D31*IF(A31<Assumptions!$B$37,Assumptions!$B$30,Assumptions!$B$36)/12) -> 6490.8556 | F31: =IF(A31>Assumptions!$B$35,0,MIN(E31,D31*Assumptions!$B$34/12)) -> 5328.3143 | G31: =E31-F31 -> 1162.5413 | H31: =IF(A31>Assumptions!$B$31,0,IF(A31<=Assumptions!$B$32+1,0,MIN(D31,PMT(IF(A31<Assumptions!$B$37,Assumptions!$B$30,Assumptions!$B$36)/12,Assumptions!$B$31-A31+1,-D31)-E31))) -> 3527.3926 | I31: =IF(A31>Assumptions!$B$31,0,IF(A31<=Assumptions!$B$32,0,IF(A31=Assumptions!$B$32+1,K30+G31,H31+G31))) -> 4689.9339 | J31: =D31-H31 -> 577743.26 | K31: =IF(A31<=Assumptions!$B$32,K30+G31,0) -> 0
A32: 28 | B32: =EDATE(DATE(2026,6,17),A32) -> 47043 | C32: =INT((A32-1)/12)+1 -> 3 | D32: =J31 -> 577743.26 | E32: =IF(A32>Assumptions!$B$31,0,D32*IF(A32<Assumptions!$B$37,Assumptions!$B$30,Assumptions!$B$36)/12) -> 6451.4664 | F32: =IF(A32>Assumptions!$B$35,0,MIN(E32,D32*Assumptions!$B$34/12)) -> 5295.9799 | G32: =E32-F32 -> 1155.4865 | H32: =IF(A32>Assumptions!$B$31,0,IF(A32<=Assumptions!$B$32+1,0,MIN(D32,PMT(IF(A32<Assumptions!$B$37,Assumptions!$B$30,Assumptions!$B$36)/12,Assumptions!$B$31-A32+1,-D32)-E32))) -> 3566.7818 | I32: =IF(A32>Assumptions!$B$31,0,IF(A32<=Assumptions!$B$32,0,IF(A32=Assumptions!$B$32+1,K31+G32,H32+G32))) -> 4722.2683 | J32: =D32-H32 -> 574176.48 | K32: =IF(A32<=Assumptions!$B$32,K31+G32,0) -> 0
A33: 29 | B33: =EDATE(DATE(2026,6,17),A33) -> 47074 | C33: =INT((A33-1)/12)+1 -> 3 | D33: =J32 -> 574176.48 | E33: =IF(A33>Assumptions!$B$31,0,D33*IF(A33<Assumptions!$B$37,Assumptions!$B$30,Assumptions!$B$36)/12) -> 6411.6373 | F33: =IF(A33>Assumptions!$B$35,0,MIN(E33,D33*Assumptions!$B$34/12)) -> 5263.2844 | G33: =E33-F33 -> 1148.353 | H33: =IF(A33>Assumptions!$B$31,0,IF(A33<=Assumptions!$B$32+1,0,MIN(D33,PMT(IF(A33<Assumptions!$B$37,Assumptions!$B$30,Assumptions!$B$36)/12,Assumptions!$B$31-A33+1,-D33)-E33))) -> 3606.6109 | I33: =IF(A33>Assumptions!$B$31,0,IF(A33<=Assumptions!$B$32,0,IF(A33=Assumptions!$B$32+1,K32+G33,H33+G33))) -> 4754.9638 | J33: =D33-H33 -> 570569.87 | K33: =IF(A33<=Assumptions!$B$32,K32+G33,0) -> 0
A34: 30 | B34: =EDATE(DATE(2026,6,17),A34) -> 47104 | C34: =INT((A34-1)/12)+1 -> 3 | D34: =J33 -> 570569.87 | E34: =IF(A34>Assumptions!$B$31,0,D34*IF(A34<Assumptions!$B$37,Assumptions!$B$30,Assumptions!$B$36)/12) -> 6371.3635 | F34: =IF(A34>Assumptions!$B$35,0,MIN(E34,D34*Assumptions!$B$34/12)) -> 5230.2238 | G34: =E34-F34 -> 1141.1397 | H34: =IF(A34>Assumptions!$B$31,0,IF(A34<=Assumptions!$B$32+1,0,MIN(D34,PMT(IF(A34<Assumptions!$B$37,Assumptions!$B$30,Assumptions!$B$36)/12,Assumptions!$B$31-A34+1,-D34)-E34))) -> 3646.8847 | I34: =IF(A34>Assumptions!$B$31,0,IF(A34<=Assumptions!$B$32,0,IF(A34=Assumptions!$B$32+1,K33+G34,H34+G34))) -> 4788.0244 | J34: =D34-H34 -> 566922.98 | K34: =IF(A34<=Assumptions!$B$32,K33+G34,0) -> 0
A35: 31 | B35: =EDATE(DATE(2026,6,17),A35) -> 47135 | C35: =INT((A35-1)/12)+1 -> 3 | D35: =J34 -> 566922.98 | E35: =IF(A35>Assumptions!$B$31,0,D35*IF(A35<Assumptions!$B$37,Assumptions!$B$30,Assumptions!$B$36)/12) -> 6330.64 | F35: =IF(A35>Assumptions!$B$35,0,MIN(E35,D35*Assumptions!$B$34/12)) -> 5196.794 | G35: =E35-F35 -> 1133.846 | H35: =IF(A35>Assumptions!$B$31,0,IF(A35<=Assumptions!$B$32+1,0,MIN(D35,PMT(IF(A35<Assumptions!$B$37,Assumptions!$B$30,Assumptions!$B$36)/12,Assumptions!$B$31-A35+1,-D35)-E35))) -> 3687.6082 | I35: =IF(A35>Assumptions!$B$31,0,IF(A35<=Assumptions!$B$32,0,IF(A35=Assumptions!$B$32+1,K34+G35,H35+G35))) -> 4821.4542 | J35: =D35-H35 -> 563235.37 | K35: =IF(A35<=Assumptions!$B$32,K34+G35,0) -> 0
A36: 32 | B36: =EDATE(DATE(2026,6,17),A36) -> 47166 | C36: =INT((A36-1)/12)+1 -> 3 | D36: =J35 -> 563235.37 | E36: =IF(A36>Assumptions!$B$31,0,D36*IF(A36<Assumptions!$B$37,Assumptions!$B$30,Assumptions!$B$36)/12) -> 6289.4617 | F36: =IF(A36>Assumptions!$B$35,0,MIN(E36,D36*Assumptions!$B$34/12)) -> 5162.9909 | G36: =E36-F36 -> 1126.4707 | H36: =IF(A36>Assumptions!$B$31,0,IF(A36<=Assumptions!$B$32+1,0,MIN(D36,PMT(IF(A36<Assumptions!$B$37,Assumptions!$B$30,Assumptions!$B$36)/12,Assumptions!$B$31-A36+1,-D36)-E36))) -> 3728.7865 | I36: =IF(A36>Assumptions!$B$31,0,IF(A36<=Assumptions!$B$32,0,IF(A36=Assumptions!$B$32+1,K35+G36,H36+G36))) -> 4855.2573 | J36: =D36-H36 -> 559506.59 | K36: =IF(A36<=Assumptions!$B$32,K35+G36,0) -> 0
A37: 33 | B37: =EDATE(DATE(2026,6,17),A37) -> 47194 | C37: =INT((A37-1)/12)+1 -> 3 | D37: =J36 -> 559506.59 | E37: =IF(A37>Assumptions!$B$31,0,D37*IF(A37<Assumptions!$B$37,Assumptions!$B$30,Assumptions!$B$36)/12) -> 6247.8236 | F37: =IF(A37>Assumptions!$B$35,0,MIN(E37,D37*Assumptions!$B$34/12)) -> 5128.8104 | G37: =E37-F37 -> 1119.0132 | H37: =IF(A37>Assumptions!$B$31,0,IF(A37<=Assumptions!$B$32+1,0,MIN(D37,PMT(IF(A37<Assumptions!$B$37,Assumptions!$B$30,Assumptions!$B$36)/12,Assumptions!$B$31-A37+1,-D37)-E37))) -> 3770.4247 | I37: =IF(A37>Assumptions!$B$31,0,IF(A37<=Assumptions!$B$32,0,IF(A37=Assumptions!$B$32+1,K36+G37,H37+G37))) -> 4889.4378 | J37: =D37-H37 -> 555736.16 | K37: =IF(A37<=Assumptions!$B$32,K36+G37,0) -> 0
A38: 34 | B38: =EDATE(DATE(2026,6,17),A38) -> 47225 | C38: =INT((A38-1)/12)+1 -> 3 | D38: =J37 -> 555736.16 | E38: =IF(A38>Assumptions!$B$31,0,D38*IF(A38<Assumptions!$B$37,Assumptions!$B$30,Assumptions!$B$36)/12) -> 6205.7205 | F38: =IF(A38>Assumptions!$B$35,0,MIN(E38,D38*Assumptions!$B$34/12)) -> 5094.2482 | G38: =E38-F38 -> 1111.4723 | H38: =IF(A38>Assumptions!$B$31,0,IF(A38<=Assumptions!$B$32+1,0,MIN(D38,PMT(IF(A38<Assumptions!$B$37,Assumptions!$B$30,Assumptions!$B$36)/12,Assumptions!$B$31-A38+1,-D38)-E38))) -> 3812.5277 | I38: =IF(A38>Assumptions!$B$31,0,IF(A38<=Assumptions!$B$32,0,IF(A38=Assumptions!$B$32+1,K37+G38,H38+G38))) -> 4924.0001 | J38: =D38-H38 -> 551923.64 | K38: =IF(A38<=Assumptions!$B$32,K37+G38,0) -> 0
A39: 35 | B39: =EDATE(DATE(2026,6,17),A39) -> 47255 | C39: =INT((A39-1)/12)+1 -> 3 | D39: =J38 -> 551923.64 | E39: =IF(A39>Assumptions!$B$31,0,D39*IF(A39<Assumptions!$B$37,Assumptions!$B$30,Assumptions!$B$36)/12) -> 6163.1473 | F39: =IF(A39>Assumptions!$B$35,0,MIN(E39,D39*Assumptions!$B$34/12)) -> 5059.3 | G39: =E39-F39 -> 1103.8473 | H39: =IF(A39>Assumptions!$B$31,0,IF(A39<=Assumptions!$B$32+1,0,MIN(D39,PMT(IF(A39<Assumptions!$B$37,Assumptions!$B$30,Assumptions!$B$36)/12,Assumptions!$B$31-A39+1,-D39)-E39))) -> 3855.101 | I39: =IF(A39>Assumptions!$B$31,0,IF(A39<=Assumptions!$B$32,0,IF(A39=Assumptions!$B$32+1,K38+G39,H39+G39))) -> 4958.9482 | J39: =D39-H39 -> 548068.53 | K39: =IF(A39<=Assumptions!$B$32,K38+G39,0) -> 0
A40: 36 | B40: =EDATE(DATE(2026,6,17),A40) -> 47286 | C40: =INT((A40-1)/12)+1 -> 3 | D40: =J39 -> 548068.53 | E40: =IF(A40>Assumptions!$B$31,0,D40*IF(A40<Assumptions!$B$37,Assumptions!$B$30,Assumptions!$B$36)/12) -> 6120.0986 | F40: =IF(A40>Assumptions!$B$35,0,MIN(E40,D40*Assumptions!$B$34/12)) -> 5023.9616 | G40: =E40-F40 -> 1096.1371 | H40: =IF(A40>Assumptions!$B$31,0,IF(A40<=Assumptions!$B$32+1,0,MIN(D40,PMT(IF(A40<Assumptions!$B$37,Assumptions!$B$30,Assumptions!$B$36)/12,Assumptions!$B$31-A40+1,-D40)-E40))) -> 3898.1496 | I40: =IF(A40>Assumptions!$B$31,0,IF(A40<=Assumptions!$B$32,0,IF(A40=Assumptions!$B$32+1,K39+G40,H40+G40))) -> 4994.2867 | J40: =D40-H40 -> 544170.38 | K40: =IF(A40<=Assumptions!$B$32,K39+G40,0) -> 0
... A124: 120 | B124: =EDATE(DATE(2026,6,17),A124) -> 49843 | C124: =INT((A124-1)/12)+1 -> 10 | D124: =J123 -> 9907.6132 | E124: =IF(A124>Assumptions!$B$31,0,D124*IF(A124<Assumptions!$B$37,Assumptions!$B$30,Assumptions!$B$36)/12) -> 110.63501 | F124: =IF(A124>Assumptions!$B$35,0,MIN(E124,D124*Assumptions!$B$34/12)) -> 0 | G124: =E124-F124 -> 110.63501 | H124: =IF(A124>Assumptions!$B$31,0,IF(A124<=Assumptions!$B$32+1,0,MIN(D124,PMT(IF(A124<Assumptions!$B$37,Assumptions!$B$30,Assumptions!$B$36)/12,Assumptions!$B$31-A124+1,-D124)-E124))) -> 9907.6132 | I124: =IF(A124>Assumptions!$B$31,0,IF(A124<=Assumptions!$B$32,0,IF(A124=Assumptions!$B$32+1,K123+G124,H124+G124))) -> 10018.248 | J124: =D124-H124 -> 8.9130481e-11 | K124: =IF(A124<=Assumptions!$B$32,K123+G124,0) -> 0
...

Sheet CF_Monthly
A1: ფულადი ნაკადი — წელი 1 / CASH FLOW — YEAR 1
A2: ყველა თანხა GEL-ში / All amounts in GEL
A4: მაჩვენებელი / Item | B4: Jan / იან | C4: Feb / თებ | D4: Mar / მარ | E4: Apr / აპრ | F4: May / მაი | G4: Jun / ივნ | H4: Jul / ივლ | I4: Aug / აგვ | J4: Sep / სექ | K4: Oct / ოქტ | L4: Nov / ნოე | M4: Dec / დეკ | N4: სულ / TOTAL
A6: გაყიდვების სეზონურობა / SALES SEASONALITY (edit the blue cells; each row must total 100%)
A7: ზამთრის მოსავლის რეალიზაცია / Winter crop sold (%) | B7: 0.2 | C7: 0.25 | D7: 0.25 | E7: 0.15 | F7: 0 | G7: 0 | H7: 0 | I7: 0 | J7: 0 | K7: 0 | L7: 0 | M7: 0.15 | N7: =SUM(B7:M7) -> 1
A8: ზაფხულის მოსავლის რეალიზაცია / Summer crop sold (%) | B8: 0 | C8: 0 | D8: 0 | E8: 0 | F8: 0 | G8: 0.2 | H8: 0.3 | I8: 0.3 | J8: 0.2 | K8: 0 | L8: 0 | M8: 0 | N8: =SUM(B8:M8) -> 1
A10: მოცულობა / VOLUME (kg)
A11: ზამთრის მოსავალი / Winter crop | B11: =Assumptions!$B$11*B7 -> 17000 | C11: =Assumptions!$B$11*C7 -> 21250 | D11: =Assumptions!$B$11*D7 -> 21250 | E11: =Assumptions!$B$11*E7 -> 12750 | F11: =Assumptions!$B$11*F7 -> 0 | G11: =Assumptions!$B$11*G7 -> 0 | H11: =Assumptions!$B$11*H7 -> 0 | I11: =Assumptions!$B$11*I7 -> 0 | ... M11: =Assumptions!$B$11*M7 -> 12750 | N11: =SUM(B11:M11) -> 85000
A12: ზაფხულის მოსავალი / Summer crop | B12: =Assumptions!$B$15*B8 -> 0 | C12: =Assumptions!$B$15*C8 -> 0 | D12: =Assumptions!$B$15*D8 -> 0 | E12: =Assumptions!$B$15*E8 -> 0 | F12: =Assumptions!$B$15*F8 -> 0 | G12: =Assumptions!$B$15*G8 -> 14000 | H12: =Assumptions!$B$15*H8 -> 21000 | I12: =Assumptions!$B$15*I8 -> 21000 | ... M12: =Assumptions!$B$15*M8 -> 0 | N12: =SUM(B12:M12) -> 70000
A13: სულ გაყიდული / Total sold | B13: =SUM(B11:B12) -> 17000 | C13: =SUM(C11:C12) -> 21250 | D13: =SUM(D11:D12) -> 21250 | E13: =SUM(E11:E12) -> 12750 | F13: =SUM(F11:F12) -> 0 | G13: =SUM(G11:G12) -> 14000 | H13: =SUM(H11:H12) -> 21000 | I13: =SUM(I11:I12) -> 21000 | ... M13: =SUM(M11:M12) -> 12750 | N13: =SUM(B13:M13) -> 155000
A15: შემოსავალი / REVENUE (GEL)
A16: ზამთრის შემოსავალი / Winter revenue | B16: =B11*Assumptions!$B$13 -> 76500 | C16: =C11*Assumptions!$B$13 -> 95625 | D16: =D11*Assumptions!$B$13 -> 95625 | E16: =E11*Assumptions!$B$13 -> 57375 | F16: =F11*Assumptions!$B$13 -> 0 | G16: =G11*Assumptions!$B$13 -> 0 | H16: =H11*Assumptions!$B$13 -> 0 | I16: =I11*Assumptions!$B$13 -> 0 | ... M16: =M11*Assumptions!$B$13 -> 57375 | N16: =SUM(B16:M16) -> 382500
A17: ზაფხულის შემოსავალი / Summer revenue | B17: =B12*Assumptions!$B$17 -> 0 | C17: =C12*Assumptions!$B$17 -> 0 | D17: =D12*Assumptions!$B$17 -> 0 | E17: =E12*Assumptions!$B$17 -> 0 | F17: =F12*Assumptions!$B$17 -> 0 | G17: =G12*Assumptions!$B$17 -> 42000 | H17: =H12*Assumptions!$B$17 -> 63000 | I17: =I12*Assumptions!$B$17 -> 63000 | ... M17: =M12*Assumptions!$B$17 -> 0 | N17: =SUM(B17:M17) -> 210000
A18: საშუალო ფასი / Realised price | B18: =IFERROR(B19/B13,0) -> 4.5 | C18: =IFERROR(C19/C13,0) -> 4.5 | D18: =IFERROR(D19/D13,0) -> 4.5 | E18: =IFERROR(E19/E13,0) -> 4.5 | F18: =IFERROR(F19/F13,0) -> 0 | G18: =IFERROR(G19/G13,0) -> 3 | H18: =IFERROR(H19/H13,0) -> 3 | I18: =IFERROR(I19/I13,0) -> 3 | ... M18: =IFERROR(M19/M13,0) -> 4.5 | N18: =IFERROR(AVERAGE(B18:M18),0) -> 2.875
A19: სულ შემოსავალი / TOTAL REVENUE | B19: =SUM(B16:B17) -> 76500 | C19: =SUM(C16:C17) -> 95625 | D19: =SUM(D16:D17) -> 95625 | E19: =SUM(E16:E17) -> 57375 | F19: =SUM(F16:F17) -> 0 | G19: =SUM(G16:G17) -> 42000 | H19: =SUM(H16:H17) -> 63000 | I19: =SUM(I16:I17) -> 63000 | ... M19: =SUM(M16:M17) -> 57375 | N19: =SUM(B19:M19) -> 592500
A21: საოპერაციო ხარჯი / OPERATING EXPENSES (GEL)
A22: ხელფასები / Labour & wages | B22: =OPEX!B19 -> 4320 | C22: =OPEX!C19 -> 4320 | D22: =OPEX!D19 -> 4320 | E22: =OPEX!E19 -> 3840 | F22: =OPEX!F19 -> 3360 | G22: =OPEX!G19 -> 4320 | H22: =OPEX!H19 -> 4320 | I22: =OPEX!I19 -> 4320 | ... M22: =OPEX!M19 -> 4320 | N22: =SUM(B22:M22) -> 48000
A23: გათბობა (გაზი/საწვავი) / Heating (gas & fuel) | B23: =OPEX!B20 -> 9000 | C23: =OPEX!C20 -> 7920 | D23: =OPEX!D20 -> 4680 | E23: =OPEX!E20 -> 1080 | F23: =OPEX!F20 -> 0 | G23: =OPEX!G20 -> 0 | H23: =OPEX!H20 -> 0 | I23: =OPEX!I20 -> 0 | ... M23: =OPEX!M20 -> 7200 | N23: =SUM(B23:M23) -> 36000
A24: ელექტროენერგია და წყალი / Electricity & water | B24: =OPEX!B21 -> 960 | C24: =OPEX!C21 -> 960 | D24: =OPEX!D21 -> 960 | E24: =OPEX!E21 -> 960 | F24: =OPEX!F21 -> 1080 | G24: =OPEX!G21 -> 1200 | H24: =OPEX!H21 -> 1320 | I24: =OPEX!I21 -> 1320 | ... M24: =OPEX!M21 -> 720 | N24: =SUM(B24:M24) -> 12000
A25: ნერგები და თესლი / Seedlings & seeds | B25: =OPEX!B22 -> 0 | C25: =OPEX!C22 -> 0 | D25: =OPEX!D22 -> 2800 | E25: =OPEX!E22 -> 3500 | F25: =OPEX!F22 -> 0 | G25: =OPEX!G22 -> 0 | H25: =OPEX!H22 -> 0 | I25: =OPEX!I22 -> 4200 | ... M25: =OPEX!M22 -> 0 | N25: =SUM(B25:M25) -> 14000
A26: სასუქი და მცენარეთა დაცვა / Fertiliser & crop protection | B26: =OPEX!B23 -> 1440 | C26: =OPEX!C23 -> 1800 | D26: =OPEX!D23 -> 2160 | E26: =OPEX!E23 -> 1800 | F26: =OPEX!F23 -> 1440 | G26: =OPEX!G23 -> 1440 | H26: =OPEX!H23 -> 1440 | I26: =OPEX!I23 -> 1440 | ... M26: =OPEX!M23 -> 720 | N26: =SUM(B26:M26) -> 18000
